<?xml version="1.0"?>
<!-- Example structure -->
<robot name="diffbot">
  <link name="base_link">
    <!-- visual, collision, inertial -->
  </link>
  
  <link name="left_wheel">
    <!-- visual, collision, inertial -->
  </link>
  
  <link name="right_wheel">
    <!-- visual, collision, inertial -->
  </link>
  
  <!-- JOINTS connecting base to wheels -->
  <joint name="left_wheel_joint" type="continuous">
    <parent link="base_link"/>
    <child link="left_wheel"/>
    <origin xyz="-0.1 0.2 0" rpy="0 0 0"/>
    <axis xyz="0 1 0"/>
  </joint>
  
  <joint name="right_wheel_joint" type="continuous">
    <parent link="base_link"/>
    <child link="right_wheel"/>
    <origin xyz="-0.1 -0.2 0" rpy="0 0 0"/>
    <axis xyz="0 1 0"/>
  </joint>
</robot>
